<?xml version="1.0"?>
<robot name="four_DoF_manipulator" xmlns:xacro="http://www.ros.org/wiki/xacro">

    <!-- This is an URDF representation of Simon's 4 DoF manipulator -->

    <xacro:include filename="properties.xacro"/>

    <!-- base_link is a large rectangular plate -->
    <link name="base_link">
        <visual>
            <origin xyz="0 0 0.02" rpy="0 0 0"/>
            <geometry>
                <box size="1 0.5 0.04"/>
            </geometry>
            <material name="white"></material>
        </visual>
        <collision>
            <origin xyz="0 0 0.02" rpy="0 0 0"/>
            <geometry>
                <box size="1 0.5 0.04"/>
            </geometry>
        </collision>
        <inertial>
            <origin xyz="0 0 0" rpy="0 0 0" />
            <mass value="0" />
            <inertia ixx="" ixy="" ixz="" iyz="" izz="" />
        </inertial>
    </link>
    
    <!-- theta_1 allows a1 to rotate with respect to base_link -->
    <!-- - Origin is set ot one of the top edges of the base_link box, so that our link skims across -->
    <!-- - It moves along the z axis -->
    <joint name="theta_1" type="revolute">
        <origin xyz="0 0 0.04" rpy="0 0 0" />
        <parent link="base_link" />
        <child link="a1" />
        <axis xyz="0 0 1" />
        <limit lower="-1.57" upper="1.57" velocity="100" effort="1000.0" />
    </joint>

    <!-- a1 link of the manipulator -->
    <!-- xacro:property name="arm_length" value="1" / -->
    <!-- xacro:property name="arm_radius" value="0.05" / -->
    <link name="a1">
        <visual>
            <origin xyz="1.5 1.5 0.225" rpy="0 0 0" />
            <geometry>
                <cylinder length="0.36" radius="0.03"/>
            </geometry>
            <material name="blue" />
        </visual>
        <collision>
            <origin xyz="1.5 1.5 0.225" rpy="0 0 0" />
            <geometry>
                <cylinder length="0.36" radius="0.03"/>
            </geometry>
        </collision>
        <inertial>
            <origin xyz="0 0 0" rpy="0 0 0" />
            <mass value="0" />
            <inertia ixx="" ixy="" ixz="" iyz="" izz="" />
        <inertial>
    </link>

    <!-- a2 link of the manipulator -->
    <link name="a2">
        <visual>
            <origin xyz="1.501 1.5 0.35" rpy="0 0 0" />
            <geometry>
                <cylinder length="0.5" radius="0.03"/>
            </geometry>
            <material name="blue" />
        </visual>
        <collision>
            <origin xyz="1.501 1.5 0.35" rpy="0 0 0" />
            <geometry>
                <cylinder length="0.5" radius="0.03"/>
            </geometry>
        </collision>
        <inertial>
            <origin xyz="0 0 0" rpy="0 0 0" />
            <mass value="0" />
            <inertia ixx="" ixy="" ixz="" iyz="" izz="" />
        <inertial>
    </link>

    <!-- theta_2 allows a3 to rotate with respect to a2 -->
    <joint name="theta_2" type="revolute">
        <origin xyz="1.502 1.5 0.35" rpy="0 0 0" />
        <parent link="a2" />
        <child link="a3" />
        <axis xyz="0 0 1" />
        <limit lower="-1.57" upper="1.57" velocity="100" effort="100" />
    </joint>

    <!-- a3 link of the manipulator -->
    <link name="a3">
        <visual>
            <origin xyz="1.507 1.5 0.35" rpy="0 0 0" />
            <geometry>
                <box size="0.1 0.02 0.02" />
            </geometry>
            <material name="blue" />
        </visual>
        <collision>
            <origin xyz="1.507 1.5 0.35" rpy="0 0 0" />
            <geometry>
                <box size="0.1 0.02 0.02" />
            </geometry>
        </collision>
        <inertial>
            <origin xyz="0 0 0" rpy="0 0 0" />
            <mass value="0" />
            <inertia ixx="" ixy="" ixz="" iyz="" izz="" />
        <inertial>
    </link>

    <!-- theta_3 allows a4 to rotate with respect to a3 -->
    <joint name="theta_3" type="revolute">
        <origin xyz="1.512 1.5 0.35" rpy="0 0 0" />
        <parent link="a3" />
        <child link="a4" />
        <!-- How are axes determined? -->
        <axis xyz="0 0 1" />
        <limit lower="-1.57" upper="1.57" velocity="100" effort="100" />
    </joint>

    <!-- a4 link of the manipulator -->
    <link name="a4">
        <visual>
            <origin xyz="1.537 1.5 0.35" rpy="0 0 0" />    
            <geometry>
                <box size="0.05 0.02 0.02" />
            </geometry>
            <material name="blue" />
        </visual>
        <collision>
            <origin xyz="1.537 1.5 0.35" rpy="0 0 0" />
            <geometry>
                <box size="0.05 0.02 0.02" />
            </geometry>
        </collision>
        <inertial>
            <origin xyz="0 0 0" rpy="0 0 0" />
            <mass value="0" />
            <inertia ixx="" ixy="" ixz="" iyz="" izz="" />
        <inertial>
    </link>

    <!-- theta_4 allows a5 to rotate with respect to a4 -->
    <joint name="theta_3" type="revolute">
        <origin xyz="1.562 1.5 0.35" rpy="0 0 0" />
        <parent link="a4" />
        <child link="a5" />
        <axis xyz="1 0 0" />
        <limit lower="-1.57" upper="1.57" velocity="100" effort="100" />
    </joint>

    <!-- a5 link of the manipulator -->
    <link name="a5">
        <visual>
            <origin xyz="1.563 1.5 0.35" rpy="0 0 0" />
            <geometry>
                <box size="0.02 0.01 0.01" />
            </geometry>
            <material name="blue" />
        </visual>
        <collision>
            <origin xyz="1.563 1.5 0.35" rpy="0 0 0" />
            <geometry>
                <box size="0.02 0.01 0.01" />
            </geometry>
        </collision>
        <inertial>
            <origin xyz="0 0 0" rpy="0 0 0" />
            <mass value="0" />
            <inertia ixx="" ixy="" ixz="" iyz="" izz="" />
        <inertial>
    </link>

</robot>